Workbook
Name Slicer_Post_Date: #N/A
Name Slicer_City: #N/A
Name Slicer_Like_Date: #N/A

Sheet Comments
A1: Comment_ID | B1: Post_ID | C1: User_ID | D1: Comment_Text | E1: Comment_Date
A2: 1 | B2: 68 | C2: 42 | D2: Total protect news response past author. | E2: 45629
A3: 2 | B3: 74 | C3: 28 | D3: Guess push nearly sit. | E3: 45780
A4: 3 | B4: 88 | C4: 24 | D4: Nation mean draw. | E4: 45604
A5: 4 | B5: 70 | C5: 1 | D5: Ago kitchen century key small. | E5: 45757
A6: 5 | B6: 76 | C6: 45 | D6: Understand plant energy apply professor defense agreement likely. | E6: 45715
A7: 6 | B7: 81 | C7: 16 | D7: Health special force city to. | E7: 45846
A8: 7 | B8: 40 | C8: 45 | D8: Check clear program cell case government add store. | E8: 45780
A9: 8 | B9: 23 | C9: 18 | D9: Perform figure beat watch as American. | E9: 45812
A10: 9 | B10: 63 | C10: 4 | D10: Short prepare machine adult peace conference expect. | E10: 45592
A11: 10 | B11: 50 | C11: 19 | D11: Point offer once wear most why them quickly. | E11: 45848
A12: 11 | B12: 18 | C12: 6 | D12: Study he particularly nor difficult. | E12: 45891
A13: 12 | B13: 60 | C13: 49 | D13: Why number return outside. | E13: 45783
... A121: 120 | B121: 4 | C121: 1 | D121: Should single officer success. | E121: 45566

Sheet Users
A1: User_ID | B1: Username | C1: Email | D1: Join_Date | E1: City
A2: 1 | B2: daniel14 | C2: tina13@hotmail.com | D2: 45335 | E2: New Krystal
A3: 2 | B3: jacksonbrianna | C3: rjohnson@mayo.com | D3: 45317 | E3: East Jennifer
A4: 3 | B4: restes | C4: heatherfernandez@jenkins-martinez.com | D4: 45238 | E4: West Richardchester
A5: 4 | B5: joshuatucker | C5: ortegathomas@gmail.com | D5: 45768 | E5: East Luisberg
A6: 5 | B6: matthew35 | C6: johnsonnathan@cruz-sullivan.com | D6: 45848 | E6: South Kylemouth
A7: 6 | B7: ghogan | C7: robert35@gmail.com | D7: 45536 | E7: Payneshire
A8: 7 | B8: costamark | C8: mercadoheidi@savage.com | D8: 45193 | E8: Taraberg
A9: 8 | B9: estradatracy | C9: porterkatherine@horton.com | D9: 45629 | E9: Leahborough
A10: 9 | B10: ahamilton | C10: qsnow@huang.net | D10: 45376 | E10: Garciashire
A11: 10 | B11: chamberslouis | C11: davidmoore@gmail.com | D11: 45344 | E11: Edwardsbury
A12: 11 | B12: georgemartin | C12: codyoconnor@lopez.com | D12: 45554 | E12: Heatherland
A13: 12 | B13: meyersjacqueline | C13: sfowler@hotmail.com | D13: 45394 | E13: Jerrychester
... A51: 50 | B51: tiffanymoore | C51: feliciapatrick@rice-schmidt.com | D51: 45556 | E51: Watsonton

Sheet Friendships
A1: Friendship_ID | B1: User_ID1 | C1: User_ID2 | D1: Since_Date
A2: 1 | B2: 16 | C2: 47 | D2: 45756
A3: 2 | B3: 43 | C3: 3 | D3: 45659
A4: 3 | B4: 5 | C4: 28 | D4: 45802
A5: 4 | B5: 2 | C5: 11 | D5: 45800
A6: 5 | B6: 38 | C6: 46 | D6: 45390
A7: 6 | B7: 15 | C7: 7 | D7: 45573
A8: 7 | B8: 43 | C8: 23 | D8: 45498
A9: 8 | B9: 21 | C9: 2 | D9: 45783
A10: 9 | B10: 38 | C10: 18 | D10: 45441
A11: 10 | B11: 30 | C11: 41 | D11: 45335
A12: 11 | B12: 24 | C12: 37 | D12: 45219
A13: 12 | B13: 13 | C13: 37 | D13: 45769
... A81: 80 | B81: 37 | C81: 49 | D81: 45425

Sheet Likes
A1: Like_ID | B1: User_ID | C1: Post_ID | D1: Like_Date
A2: 1 | B2: 30 | C2: 33 | D2: 45639
A3: 2 | B3: 20 | C3: 7 | D3: 45558
A4: 3 | B4: 10 | C4: 78 | D4: 45606
A5: 4 | B5: 39 | C5: 63 | D5: 45819
A6: 5 | B6: 17 | C6: 27 | D6: 45575
A7: 6 | B7: 20 | C7: 87 | D7: 45567
A8: 7 | B8: 47 | C8: 65 | D8: 45882
A9: 8 | B9: 35 | C9: 90 | D9: 45652
A10: 9 | B10: 22 | C10: 63 | D10: 45801
A11: 10 | B11: 47 | C11: 96 | D11: 45879
A12: 11 | B12: 6 | C12: 95 | D12: 45698
A13: 12 | B13: 22 | C13: 50 | D13: 45911
... A151: 150 | B151: 17 | C151: 80 | D151: 45691

Sheet Posts
A1: Post_ID | B1: User_ID | C1: Content_Length | D1: Post_Date
A2: 1 | B2: 13 | C2: 191 | D2: 45659
A3: 2 | B3: 8 | C3: 175 | D3: 45647
A4: 3 | B4: 18 | C4: 23 | D4: 45624
A5: 4 | B5: 2 | C5: 152 | D5: 45624
A6: 5 | B6: 5 | C6: 112 | D6: 45841
A7: 6 | B7: 49 | C7: 22 | D7: 45887
A8: 7 | B8: 8 | C8: 92 | D8: 45737
A9: 8 | B9: 13 | C9: 69 | D9: 45551
A10: 9 | B10: 14 | C10: 70 | D10: 45779
A11: 10 | B11: 11 | C11: 187 | D11: 45703
A12: 11 | B12: 40 | C12: 67 | D12: 45694
A13: 12 | B13: 45 | C13: 96 | D13: 45728
... A101: 100 | B101: 40 | C101: 51 | D101: 45630

Sheet pvt_dashboard

Sheet cleaned_data_formulas_functions
A1: User_ID | B1: Username | C1: Email | D1: Join_Date | E1: City | F1: domain | G1: post_count | H1: Avg_cont_length | I1: Likes_given | J1: comments_given | K1: Total_act | L1: user_name | M1: duration_months | N1: Post_ID | O1: Like_ID | P1: Comment_ID | Q1: Post_Date
A2: 1 | B2: daniel14 | C2: tina13@hotmail.com | D2: 45335 | E2: New Krystal | F2: hotmail.com | G2: =COUNTIF(Posts!B:B,Users!A2) -> 2 | H2: =AVERAGEIF(Posts!B:B,Users!A2,Posts!C:C) -> 47 | I2: =COUNTIF(Likes!B:B,Users!A2) -> 6 | J2: =COUNTIF(Comments!C:C,Users!A2) -> 5 | K2: =SUM(I2+J2) -> 11 | L2: =_xlfn.XLOOKUP(Comments!C2,Users!A:A,Users!B:B,"Not Found") -> lindadelgado | M2: =DATEDIF(Friendships!D2,TODAY(),"M") -> 5 | N2: 1 | O2: 1 | P2: 1 | Q2: 45659
A3: 2 | B3: jacksonbrianna | C3: rjohnson@mayo.com | D3: 45317 | E3: East Jennifer | F3: mayo.com | G3: =COUNTIF(Posts!B:B,Users!A3) -> 2 | H3: =AVERAGEIF(Posts!B:B,Users!A3,Posts!C:C) -> 145.5 | I3: =COUNTIF(Likes!B:B,Users!A3) -> 1 | J3: =COUNTIF(Comments!C:C,Users!A3) -> 1 | K3: =SUM(I3+J3) -> 2 | L3: =_xlfn.XLOOKUP(Comments!C3,Users!A:A,Users!B:B,"Not Found") -> kristendecker | M3: =DATEDIF(Friendships!D3,TODAY(),"M") -> 8 | N3: 2 | O3: 2 | P3: 2 | Q3: 45647
A4: 3 | B4: restes | C4: heatherfernandez@jenkins-martinez.com | D4: 45238 | E4: West Richardchester | F4: jenkins-martinez.com | G4: =COUNTIF(Posts!B:B,Users!A4) -> 2 | H4: =AVERAGEIF(Posts!B:B,Users!A4,Posts!C:C) -> 83 | I4: =COUNTIF(Likes!B:B,Users!A4) -> 2 | J4: =COUNTIF(Comments!C:C,Users!A4) -> 3 | K4: =SUM(I4+J4) -> 5 | L4: =_xlfn.XLOOKUP(Comments!C4,Users!A:A,Users!B:B,"Not Found") -> privera | M4: =DATEDIF(Friendships!D4,TODAY(),"M") -> 3 | N4: 3 | O4: 3 | P4: 3 | Q4: 45624
A5: 4 | B5: joshuatucker | C5: ortegathomas@gmail.com | D5: 45768 | E5: East Luisberg | F5: gmail.com | G5: =COUNTIF(Posts!B:B,Users!A5) -> 2 | H5: =AVERAGEIF(Posts!B:B,Users!A5,Posts!C:C) -> 136 | I5: =COUNTIF(Likes!B:B,Users!A5) -> 5 | J5: =COUNTIF(Comments!C:C,Users!A5) -> 3 | K5: =SUM(I5+J5) -> 8 | L5: =_xlfn.XLOOKUP(Comments!C5,Users!A:A,Users!B:B,"Not Found") -> daniel14 | M5: =DATEDIF(Friendships!D5,TODAY(),"M") -> 3 | N5: 4 | O5: 4 | P5: 4 | Q5: 45624
A6: 5 | B6: matthew35 | C6: johnsonnathan@cruz-sullivan.com | D6: 45848 | E6: South Kylemouth | F6: cruz-sullivan.com | G6: =COUNTIF(Posts!B:B,Users!A6) -> 2 | H6: =AVERAGEIF(Posts!B:B,Users!A6,Posts!C:C) -> 75 | I6: =COUNTIF(Likes!B:B,Users!A6) -> 2 | J6: =COUNTIF(Comments!C:C,Users!A6) -> 1 | K6: =SUM(I6+J6) -> 3 | L6: =_xlfn.XLOOKUP(Comments!C6,Users!A:A,Users!B:B,"Not Found") -> rebeccapacheco | M6: =DATEDIF(Friendships!D6,TODAY(),"M") -> 17 | N6: 5 | O6: 5 | P6: 5 | Q6: 45841
A7: 6 | B7: ghogan | C7: robert35@gmail.com | D7: 45536 | E7: Payneshire | F7: gmail.com | G7: =COUNTIF(Posts!B:B,Users!A7) -> 2 | H7: =AVERAGEIF(Posts!B:B,Users!A7,Posts!C:C) -> 47.5 | I7: =COUNTIF(Likes!B:B,Users!A7) -> 2 | J7: =COUNTIF(Comments!C:C,Users!A7) -> 2 | K7: =SUM(I7+J7) -> 4 | L7: =_xlfn.XLOOKUP(Comments!C7,Users!A:A,Users!B:B,"Not Found") -> ericabaker | M7: =DATEDIF(Friendships!D7,TODAY(),"M") -> 11 | N7: 6 | O7: 6 | P7: 6 | Q7: 45887
A8: 7 | B8: costamark | C8: mercadoheidi@savage.com | D8: 45193 | E8: Taraberg | F8: savage.com | G8: =COUNTIF(Posts!B:B,Users!A8) -> 2 | H8: =AVERAGEIF(Posts!B:B,Users!A8,Posts!C:C) -> 95.5 | I8: =COUNTIF(Likes!B:B,Users!A8) -> 5 | J8: =COUNTIF(Comments!C:C,Users!A8) -> 3 | K8: =SUM(I8+J8) -> 8 | L8: =_xlfn.XLOOKUP(Comments!C8,Users!A:A,Users!B:B,"Not Found") -> rebeccapacheco | M8: =DATEDIF(Friendships!D8,TODAY(),"M") -> 13 | N8: 7 | O8: 7 | P8: 7 | Q8: 45737
A9: 8 | B9: estradatracy | C9: porterkatherine@horton.com | D9: 45629 | E9: Leahborough | F9: horton.com | G9: =COUNTIF(Posts!B:B,Users!A9) -> 4 | H9: =AVERAGEIF(Posts!B:B,Users!A9,Posts!C:C) -> 116.25 | I9: =COUNTIF(Likes!B:B,Users!A9) -> 2 | J9: =COUNTIF(Comments!C:C,Users!A9) -> 2 | K9: =SUM(I9+J9) -> 4 | L9: =_xlfn.XLOOKUP(Comments!C9,Users!A:A,Users!B:B,"Not Found") -> oromero | M9: =DATEDIF(Friendships!D9,TODAY(),"M") -> 4 | N9: 8 | O9: 8 | P9: 8 | Q9: 45551
A10: 9 | B10: ahamilton | C10: qsnow@huang.net | D10: 45376 | E10: Garciashire | F10: huang.net | G10: =COUNTIF(Posts!B:B,Users!A10) -> 2 | H10: =AVERAGEIF(Posts!B:B,Users!A10,Posts!C:C) -> 117 | I10: =COUNTIF(Likes!B:B,Users!A10) -> 0 | J10: =COUNTIF(Comments!C:C,Users!A10) -> 2 | K10: =SUM(I10+J10) -> 2 | L10: =_xlfn.XLOOKUP(Comments!C10,Users!A:A,Users!B:B,"Not Found") -> joshuatucker | M10: =DATEDIF(Friendships!D10,TODAY(),"M") -> 15 | N10: 9 | O10: 9 | P10: 9 | Q10: 45779
A11: 10 | B11: chamberslouis | C11: davidmoore@gmail.com | D11: 45344 | E11: Edwardsbury | F11: gmail.com | G11: =COUNTIF(Posts!B:B,Users!A11) -> 0 | H11: 0 | I11: =COUNTIF(Likes!B:B,Users!A11) -> 7 | J11: =COUNTIF(Comments!C:C,Users!A11) -> 1 | K11: =SUM(I11+J11) -> 8 | L11: =_xlfn.XLOOKUP(Comments!C11,Users!A:A,Users!B:B,"Not Found") -> bassjason | M11: =DATEDIF(Friendships!D11,TODAY(),"M") -> 19 | N11: 10 | O11: 10 | P11: 10 | Q11: 45703
A12: 11 | B12: georgemartin | C12: codyoconnor@lopez.com | D12: 45554 | E12: Heatherland | F12: lopez.com | G12: =COUNTIF(Posts!B:B,Users!A12) -> 6 | H12: =AVERAGEIF(Posts!B:B,Users!A12,Posts!C:C) -> 124.83333 | I12: =COUNTIF(Likes!B:B,Users!A12) -> 3 | J12: =COUNTIF(Comments!C:C,Users!A12) -> 0 | K12: =SUM(I12+J12) -> 3 | L12: =_xlfn.XLOOKUP(Comments!C12,Users!A:A,Users!B:B,"Not Found") -> ghogan | M12: =DATEDIF(Friendships!D12,TODAY(),"M") -> 23 | N12: 11 | O12: 11 | P12: 11 | Q12: 45694
A13: 12 | B13: meyersjacqueline | C13: sfowler@hotmail.com | D13: 45394 | E13: Jerrychester | F13: hotmail.com | G13: =COUNTIF(Posts!B:B,Users!A13) -> 1 | H13: =AVERAGEIF(Posts!B:B,Users!A13,Posts!C:C) -> 114 | I13: =COUNTIF(Likes!B:B,Users!A13) -> 0 | J13: =COUNTIF(Comments!C:C,Users!A13) -> 2 | K13: =SUM(I13+J13) -> 2 | L13: =_xlfn.XLOOKUP(Comments!C13,Users!A:A,Users!B:B,"Not Found") -> pgarcia | M13: =DATEDIF(Friendships!D13,TODAY(),"M") -> 5 | N13: 12 | O13: 12 | P13: 12 | Q13: 45728
A14: 13 | B14: ronald33 | C14: nlarson@delgado.net | D14: 45596 | E14: Stephenbury | F14: delgado.net | G14: =COUNTIF(Posts!B:B,Users!A14) -> 3 | H14: =AVERAGEIF(Posts!B:B,Users!A14,Posts!C:C) -> 149.66667 | I14: =COUNTIF(Likes!B:B,Users!A14) -> 3 | J14: =COUNTIF(Comments!C:C,Users!A14) -> 1 | K14: =SUM(I14+J14) -> 4 | L14: =_xlfn.XLOOKUP(Comments!C14,Users!A:A,Users!B:B,"Not Found") -> kristendecker | M14: =DATEDIF(Friendships!D14,TODAY(),"M") -> 20 | N14: 13 | O14: 13 | P14: 13 | Q14: 45850
A15: 14 | B15: williamsrobert | C15: michael13@graves.com | D15: 45820 | E15: Andreaborough | F15: graves.com | G15: =COUNTIF(Posts!B:B,Users!A15) -> 2 | H15: =AVERAGEIF(Posts!B:B,Users!A15,Posts!C:C) -> 131.5 | I15: =COUNTIF(Likes!B:B,Users!A15) -> 4 | J15: =COUNTIF(Comments!C:C,Users!A15) -> 1 | K15: =SUM(I15+J15) -> 5 | L15: =_xlfn.XLOOKUP(Comments!C15,Users!A:A,Users!B:B,"Not Found") -> taylorclark | M15: =DATEDIF(Friendships!D15,TODAY(),"M") -> 15 | N15: 14 | O15: 14 | P15: 14 | Q15: 45554
A16: 15 | B16: seandonaldson | C16: bushandrew@norton.info | D16: 45476 | E16: Morrisfurt | F16: norton.info | G16: =COUNTIF(Posts!B:B,Users!A16) -> 1 | H16: =AVERAGEIF(Posts!B:B,Users!A16,Posts!C:C) -> 43 | I16: =COUNTIF(Likes!B:B,Users!A16) -> 2 | J16: =COUNTIF(Comments!C:C,Users!A16) -> 1 | K16: =SUM(I16+J16) -> 3 | L16: =_xlfn.XLOOKUP(Comments!C16,Users!A:A,Users!B:B,"Not Found") -> ghogan | M16: =DATEDIF(Friendships!D16,TODAY(),"M") -> 4 | N16: 15 | O16: 15 | P16: 15 | Q16: 45776
A17: 16 | B17: ericabaker | C17: grahamdesiree@griffin-herring.com | D17: 45372 | E17: East Taylorfurt | F17: griffin-herring.com | G17: =COUNTIF(Posts!B:B,Users!A17) -> 2 | H17: =AVERAGEIF(Posts!B:B,Users!A17,Posts!C:C) -> 81.5 | I17: =COUNTIF(Likes!B:B,Users!A17) -> 2 | J17: =COUNTIF(Comments!C:C,Users!A17) -> 5 | K17: =SUM(I17+J17) -> 7 | L17: =_xlfn.XLOOKUP(Comments!C17,Users!A:A,Users!B:B,"Not Found") -> vbutler | M17: =DATEDIF(Friendships!D17,TODAY(),"M") -> 20 | N17: 16 | O17: 16 | P17: 16 | Q17: 45705
A18: 17 | B18: smithlogan | C18: millerkyle@gmail.com | D18: 45217 | E18: Kathyview | F18: gmail.com | G18: =COUNTIF(Posts!B:B,Users!A18) -> 3 | H18: =AVERAGEIF(Posts!B:B,Users!A18,Posts!C:C) -> 45.666667 | I18: =COUNTIF(Likes!B:B,Users!A18) -> 7 | J18: =COUNTIF(Comments!C:C,Users!A18) -> 1 | K18: =SUM(I18+J18) -> 8 | L18: =_xlfn.XLOOKUP(Comments!C18,Users!A:A,Users!B:B,"Not Found") -> tiffanymoore | M18: =DATEDIF(Friendships!D18,TODAY(),"M") -> 23 | N18: 17 | O18: 17 | P18: 17 | Q18: 45760
A19: 18 | B19: oromero | C19: roberthicks@smith-robertson.com | D19: 45669 | E19: Mooreshire | F19: smith-robertson.com | G19: =COUNTIF(Posts!B:B,Users!A19) -> 1 | H19: =AVERAGEIF(Posts!B:B,Users!A19,Posts!C:C) -> 23 | I19: =COUNTIF(Likes!B:B,Users!A19) -> 2 | J19: =COUNTIF(Comments!C:C,Users!A19) -> 2 | K19: =SUM(I19+J19) -> 4 | L19: =_xlfn.XLOOKUP(Comments!C19,Users!A:A,Users!B:B,"Not Found") -> vbutler | M19: =DATEDIF(Friendships!D19,TODAY(),"M") -> 7 | N19: 18 | O19: 18 | P19: 18 | Q19: 45639
A20: 19 | B20: bassjason | C20: joshuabell@gmail.com | D20: 45526 | E20: Hunterland | F20: gmail.com | G20: =COUNTIF(Posts!B:B,Users!A20) -> 4 | H20: =AVERAGEIF(Posts!B:B,Users!A20,Posts!C:C) -> 107.25 | I20: =COUNTIF(Likes!B:B,Users!A20) -> 1 | J20: =COUNTIF(Comments!C:C,Users!A20) -> 2 | K20: =SUM(I20+J20) -> 3 | L20: =_xlfn.XLOOKUP(Comments!C20,Users!A:A,Users!B:B,"Not Found") -> vbutler | M20: =DATEDIF(Friendships!D20,TODAY(),"M") -> 19 | N20: 19 | O20: 19 | P20: 19 | Q20: 45794
A21: 20 | B21: haledavid | C21: eric01@long-golden.biz | D21: 45609 | E21: Danielhaven | F21: long-golden.biz | G21: =COUNTIF(Posts!B:B,Users!A21) -> 2 | H21: =AVERAGEIF(Posts!B:B,Users!A21,Posts!C:C) -> 121 | I21: =COUNTIF(Likes!B:B,Users!A21) -> 4 | J21: =COUNTIF(Comments!C:C,Users!A21) -> 3 | K21: =SUM(I21+J21) -> 7 | L21: =_xlfn.XLOOKUP(Comments!C21,Users!A:A,Users!B:B,"Not Found") -> oromero | M21: =DATEDIF(Friendships!D21,TODAY(),"M") -> 7 | N21: 20 | O21: 20 | P21: 20 | Q21: 45621
A22: 21 | B22: carpentermckenzie | C22: tammiemiller@yahoo.com | D22: 45883 | E22: Cruzfurt | F22: yahoo.com | G22: =COUNTIF(Posts!B:B,Users!A22) -> 1 | H22: =AVERAGEIF(Posts!B:B,Users!A22,Posts!C:C) -> 85 | I22: =COUNTIF(Likes!B:B,Users!A22) -> 7 | J22: =COUNTIF(Comments!C:C,Users!A22) -> 3 | K22: =SUM(I22+J22) -> 10 | L22: =_xlfn.XLOOKUP(Comments!C22,Users!A:A,Users!B:B,"Not Found") -> pgarcia | M22: =DATEDIF(Friendships!D22,TODAY(),"M") -> 16 | N22: 21 | O22: 21 | P22: 21 | Q22: 45801
A23: 22 | B23: erikaphillips | C23: franklinamanda@hicks.com | D23: 45798 | E23: Calderonbury | F23: hicks.com | G23: =COUNTIF(Posts!B:B,Users!A23) -> 5 | H23: =AVERAGEIF(Posts!B:B,Users!A23,Posts!C:C) -> 105.4 | I23: =COUNTIF(Likes!B:B,Users!A23) -> 2 | J23: =COUNTIF(Comments!C:C,Users!A23) -> 4 | K23: =SUM(I23+J23) -> 6 | L23: =_xlfn.XLOOKUP(Comments!C23,Users!A:A,Users!B:B,"Not Found") -> kristendecker | M23: =DATEDIF(Friendships!D23,TODAY(),"M") -> 13 | N23: 22 | O23: 22 | P23: 22 | Q23: 45750
... A26: 25 | B26: abigailmercer | C26: kevinporter@schneider.org | D26: 45853 | E26: Kennethside | F26: schneider.org | G26: =COUNTIF(Posts!B:B,Users!A26) -> 3 | H26: =AVERAGEIF(Posts!B:B,Users!A26,Posts!C:C) -> 95.333333 | I26: =COUNTIF(Likes!B:B,Users!A26) -> 2 | J26: =COUNTIF(Comments!C:C,Users!A26) -> 4 | K26: =SUM(I26+J26) -> 6 | L26: =_xlfn.XLOOKUP(Comments!C26,Users!A:A,Users!B:B,"Not Found") -> carrillotiffany | M26: =DATEDIF(Friendships!D26,TODAY(),"M") -> 16 | N26: 25 | O26: 25 | P26: 25 | Q26: 45660
A27: 26 | B27: mbush | C27: xdecker@yahoo.com | D27: 45481 | E27: Codyview | F27: yahoo.com | G27: =COUNTIF(Posts!B:B,Users!A27) -> 0 | H27: 0 | I27: =COUNTIF(Likes!B:B,Users!A27) -> 2 | J27: =COUNTIF(Comments!C:C,Users!A27) -> 0 | K27: =SUM(I27+J27) -> 2 | L27: =_xlfn.XLOOKUP(Comments!C27,Users!A:A,Users!B:B,"Not Found") -> meyersjacqueline | M27: =DATEDIF(Friendships!D27,TODAY(),"M") -> 4 | N27: 26 | O27: 26 | P27: 26 | Q27: 45891
A28: 27 | B28: taylorclark | C28: amanda22@thomas-newman.biz | D28: 45846 | E28: Walterland | F28: thomas-newman.biz | G28: =COUNTIF(Posts!B:B,Users!A28) -> 3 | H28: =AVERAGEIF(Posts!B:B,Users!A28,Posts!C:C) -> 132.66667 | I28: =COUNTIF(Likes!B:B,Users!A28) -> 4 | J28: =COUNTIF(Comments!C:C,Users!A28) -> 3 | K28: =SUM(I28+J28) -> 7 | L28: =_xlfn.XLOOKUP(Comments!C28,Users!A:A,Users!B:B,"Not Found") -> haledavid | M28: =DATEDIF(Friendships!D28,TODAY(),"M") -> 21 | N28: 27 | O28: 27 | P28: 27 | Q28: 45693
A29: 28 | B29: kristendecker | C29: benjamincox@graham.biz | D29: 45194 | E29: Lauraberg | F29: graham.biz | G29: =COUNTIF(Posts!B:B,Users!A29) -> 0 | H29: 0 | I29: =COUNTIF(Likes!B:B,Users!A29) -> 3 | J29: =COUNTIF(Comments!C:C,Users!A29) -> 4 | K29: =SUM(I29+J29) -> 7 | L29: =_xlfn.XLOOKUP(Comments!C29,Users!A:A,Users!B:B,"Not Found") -> victorjackson | M29: =DATEDIF(Friendships!D29,TODAY(),"M") -> 11 | N29: 28 | O29: 28 | P29: 28 | Q29: 45676
A30: 29 | B30: ssharp | C30: mmurray@hotmail.com | D30: 45405 | E30: North Benjamin | F30: hotmail.com | G30: =COUNTIF(Posts!B:B,Users!A30) -> 1 | H30: =AVERAGEIF(Posts!B:B,Users!A30,Posts!C:C) -> 48 | I30: =COUNTIF(Likes!B:B,Users!A30) -> 2 | J30: =COUNTIF(Comments!C:C,Users!A30) -> 5 | K30: =SUM(I30+J30) -> 7 | L30: =_xlfn.XLOOKUP(Comments!C30,Users!A:A,Users!B:B,"Not Found") -> jacksonbrianna | M30: =DATEDIF(Friendships!D30,TODAY(),"M") -> 9 | N30: 29 | O30: 29 | P30: 29 | Q30: 45618
A31: 30 | B31: victorjackson | C31: henryblake@yahoo.com | D31: 45268 | E31: North Shawnfurt | F31: yahoo.com | G31: =COUNTIF(Posts!B:B,Users!A31) -> 3 | H31: =AVERAGEIF(Posts!B:B,Users!A31,Posts!C:C) -> 141.33333 | I31: =COUNTIF(Likes!B:B,Users!A31) -> 6 | J31: =COUNTIF(Comments!C:C,Users!A31) -> 4 | K31: =SUM(I31+J31) -> 10 | L31: =_xlfn.XLOOKUP(Comments!C31,Users!A:A,Users!B:B,"Not Found") -> abigailmercer | M31: =DATEDIF(Friendships!D31,TODAY(),"M") -> 23 | N31: 30 | O31: 30 | P31: 30 | Q31: 45626
A32: 31 | B32: timothy51 | C32: laurie37@cook.com | D32: 45548 | E32: Lake Nathan | F32: cook.com | G32: =COUNTIF(Posts!B:B,Users!A32) -> 1 | H32: =AVERAGEIF(Posts!B:B,Users!A32,Posts!C:C) -> 40 | I32: =COUNTIF(Likes!B:B,Users!A32) -> 2 | J32: =COUNTIF(Comments!C:C,Users!A32) -> 0 | K32: =SUM(I32+J32) -> 2 | L32: =_xlfn.XLOOKUP(Comments!C32,Users!A:A,Users!B:B,"Not Found") -> meyersjacqueline | M32: =DATEDIF(Friendships!D32,TODAY(),"M") -> 1 | N32: 31 | O32: 31 | P32: 31 | Q32: 45678
A33: 32 | B33: lucerodavid | C33: schroederdennis@gmail.com | D33: 45893 | E33: North Amandaton | F33: gmail.com | G33: =COUNTIF(Posts!B:B,Users!A33) -> 0 | H33: 0 | I33: =COUNTIF(Likes!B:B,Users!A33) -> 3 | J33: =COUNTIF(Comments!C:C,Users!A33) -> 5 | K33: =SUM(I33+J33) -> 8 | L33: =_xlfn.XLOOKUP(Comments!C33,Users!A:A,Users!B:B,"Not Found") -> samuel65 | M33: =DATEDIF(Friendships!D33,TODAY(),"M") -> 23 | N33: 32 | O33: 32 | P33: 32 | Q33: 45781
A34: 33 | B34: jonessydney | C34: courtneyheath@gregory.biz | D34: 45265 | E34: East Sharontown | F34: gregory.biz | G34: =COUNTIF(Posts!B:B,Users!A34) -> 2 | H34: =AVERAGEIF(Posts!B:B,Users!A34,Posts!C:C) -> 56 | I34: =COUNTIF(Likes!B:B,Users!A34) -> 5 | J34: =COUNTIF(Comments!C:C,Users!A34) -> 3 | K34: =SUM(I34+J34) -> 8 | L34: =_xlfn.XLOOKUP(Comments!C34,Users!A:A,Users!B:B,"Not Found") -> restes | M34: =DATEDIF(Friendships!D34,TODAY(),"M") -> 6 | N34: 33 | O34: 33 | P34: 33 | Q34: 45736
A35: 34 | B35: carrillotiffany | C35: imartinez@yahoo.com | D35: 45561 | E35: Seanville | F35: yahoo.com | G35: =COUNTIF(Posts!B:B,Users!A35) -> 2 | H35: =AVERAGEIF(Posts!B:B,Users!A35,Posts!C:C) -> 94 | I35: =COUNTIF(Likes!B:B,Users!A35) -> 0 | J35: =COUNTIF(Comments!C:C,Users!A35) -> 4 | K35: =SUM(I35+J35) -> 4 | L35: =_xlfn.XLOOKUP(Comments!C35,Users!A:A,Users!B:B,"Not Found") -> lucerodavid | M35: =DATEDIF(Friendships!D35,TODAY(),"M") -> 15 | N35: 34 | O35: 34 | P35: 34 | Q35: 45682
A36: 35 | B36: leegina | C36: jrobinson@yahoo.com | D36: 45703 | E36: Port Susanfort | F36: yahoo.com | G36: =COUNTIF(Posts!B:B,Users!A36) -> 1 | H36: =AVERAGEIF(Posts!B:B,Users!A36,Posts!C:C) -> 52 | I36: =COUNTIF(Likes!B:B,Users!A36) -> 3 | J36: =COUNTIF(Comments!C:C,Users!A36) -> 1 | K36: =SUM(I36+J36) -> 4 | L36: =_xlfn.XLOOKUP(Comments!C36,Users!A:A,Users!B:B,"Not Found") -> williamsrobert | M36: =DATEDIF(Friendships!D36,TODAY(),"M") -> 15 | N36: 35 | O36: 35 | P36: 35 | Q36: 45573
A37: 36 | B37: larry37 | C37: lindseyroy@yahoo.com | D37: 45723 | E37: East Melissaville | F37: yahoo.com | G37: =COUNTIF(Posts!B:B,Users!A37) -> 1 | H37: =AVERAGEIF(Posts!B:B,Users!A37,Posts!C:C) -> 53 | I37: =COUNTIF(Likes!B:B,Users!A37) -> 3 | J37: =COUNTIF(Comments!C:C,Users!A37) -> 3 | K37: =SUM(I37+J37) -> 6 | L37: =_xlfn.XLOOKUP(Comments!C37,Users!A:A,Users!B:B,"Not Found") -> weavergina | M37: =DATEDIF(Friendships!D37,TODAY(),"M") -> 23 | N37: 36 | O37: 36 | P37: 36 | Q37: 45592
A38: 37 | B38: ljohnson | C38: coreythomas@yahoo.com | D38: 45284 | E38: East Willieton | F38: yahoo.com | G38: =COUNTIF(Posts!B:B,Users!A38) -> 0 | H38: 0 | I38: =COUNTIF(Likes!B:B,Users!A38) -> 1 | J38: =COUNTIF(Comments!C:C,Users!A38) -> 0 | K38: =SUM(I38+J38) -> 1 | L38: =_xlfn.XLOOKUP(Comments!C38,Users!A:A,Users!B:B,"Not Found") -> lucerodavid | M38: =DATEDIF(Friendships!D38,TODAY(),"M") -> 14 | N38: 37 | O38: 37 | P38: 37 | Q38: 45775
A39: 38 | B39: christian06 | C39: dennis81@clayton-gonzalez.com | D39: 45824 | E39: South Brendafurt | F39: clayton-gonzalez.com | G39: =COUNTIF(Posts!B:B,Users!A39) -> 2 | H39: =AVERAGEIF(Posts!B:B,Users!A39,Posts!C:C) -> 161.5 | I39: =COUNTIF(Likes!B:B,Users!A39) -> 4 | J39: =COUNTIF(Comments!C:C,Users!A39) -> 2 | K39: =SUM(I39+J39) -> 6 | L39: =_xlfn.XLOOKUP(Comments!C39,Users!A:A,Users!B:B,"Not Found") -> lucerodavid | M39: =DATEDIF(Friendships!D39,TODAY(),"M") -> 7 | N39: 38 | O39: 38 | P39: 38 | Q39: 45582
A40: 39 | B40: traviscarr | C40: gordonbrandon@morales.org | D40: 45197 | E40: Bushstad | F40: morales.org | G40: =COUNTIF(Posts!B:B,Users!A40) -> 2 | H40: =AVERAGEIF(Posts!B:B,Users!A40,Posts!C:C) -> 71 | I40: =COUNTIF(Likes!B:B,Users!A40) -> 3 | J40: =COUNTIF(Comments!C:C,Users!A40) -> 0 | K40: =SUM(I40+J40) -> 3 | L40: =_xlfn.XLOOKUP(Comments!C40,Users!A:A,Users!B:B,"Not Found") -> ahamilton | M40: =DATEDIF(Friendships!D40,TODAY(),"M") -> 3 | N40: 39 | O40: 39 | P40: 39 | Q40: 45788
A41: 40 | B41: znelson | C41: jonesbrandon@buchanan-sawyer.com | D41: 45464 | E41: Amandafurt | F41: buchanan-sawyer.com | G41: =COUNTIF(Posts!B:B,Users!A41) -> 2 | H41: =AVERAGEIF(Posts!B:B,Users!A41,Posts!C:C) -> 59 | I41: =COUNTIF(Likes!B:B,Users!A41) -> 3 | J41: =COUNTIF(Comments!C:C,Users!A41) -> 2 | K41: =SUM(I41+J41) -> 5 | L41: =_xlfn.XLOOKUP(Comments!C41,Users!A:A,Users!B:B,"Not Found") -> smithlogan | M41: =DATEDIF(Friendships!D41,TODAY(),"M") -> 19 | N41: 40 | O41: 40 | P41: 40 | Q41: 45812
A42: 41 | B42: samuel65 | C42: rileyjason@keller.com | D42: 45415 | E42: New David | F42: keller.com | G42: =COUNTIF(Posts!B:B,Users!A42) -> 3 | H42: =AVERAGEIF(Posts!B:B,Users!A42,Posts!C:C) -> 89 | I42: =COUNTIF(Likes!B:B,Users!A42) -> 2 | J42: =COUNTIF(Comments!C:C,Users!A42) -> 1 | K42: =SUM(I42+J42) -> 3 | L42: =_xlfn.XLOOKUP(Comments!C42,Users!A:A,Users!B:B,"Not Found") -> kevinhampton | M42: =DATEDIF(Friendships!D42,TODAY(),"M") -> 10 | N42: 41 | O42: 41 | P42: 41 | Q42: 45700
...

Sheet pivot_tables
A3: City | B3: Sum of Post_ID | C3: Sum of User_ID | D3: Sum of Like_ID | F3: Post_ID | G3: Sum of comments_given | H3: Sum of Likes_given | K3: Post_ID | L3: Count of Like_ID | N3: Post_Date | O3: Count of Like_ID | P3: Count of Post_ID | Q3: Count of Comment_ID
A4: Amandafurt | B4: 40 | C4: 40 | D4: 40 | F4: 1 | G4: 5 | H4: 6 | K4: 91 | L4: 5 | N4: 45551 | O4: 1 | P4: 1 | Q4: 1
A5: Andreaborough | B5: 14 | C5: 14 | D5: 14 | F5: 2 | G5: 1 | H5: 1 | K5: 63 | L5: 5 | N5: 45554 | O5: 3 | P5: 3 | Q5: 3
A6: Bushstad | B6: 39 | C6: 39 | D6: 39 | F6: 3 | G6: 3 | H6: 2 | K6: 92 | L6: 4 | N6: 45564 | O6: 1 | P6: 1 | Q6: 1
A7: Calderonbury | B7: 22 | C7: 22 | D7: 22 | F7: 4 | G7: 3 | H7: 5 | K7: 73 | L7: 4 | N7: 45566 | O7: 2 | P7: 2 | Q7: 2
A8: Christopherside | B8: 42 | C8: 42 | D8: 42 | F8: 5 | G8: 1 | H8: 2 | K8: 51 | L8: 4 | N8: 45572 | O8: 1 | P8: 1 | Q8: 1
A9: Codyview | B9: 26 | C9: 26 | D9: 26 | F9: 6 | G9: 2 | H9: 2 | K9: 46 | L9: 4 | N9: 45573 | O9: 1 | P9: 1 | Q9: 1
A10: Cruzfurt | B10: 21 | C10: 21 | D10: 21 | F10: 7 | G10: 3 | H10: 5 | K10: 33 | L10: 4 | N10: 45575 | O10: 1 | P10: 1 | Q10: 1
A11: Danielhaven | B11: 20 | C11: 20 | D11: 20 | F11: 8 | G11: 2 | H11: 2 | K11: 7 | L11: 4 | N11: 45582 | O11: 1 | P11: 1 | Q11: 1
A12: Davidville | B12: 44 | C12: 44 | D12: 44 | F12: 9 | G12: 2 | H12: 0 | K12: 94 | L12: 3 | N12: 45587 | O12: 1 | P12: 1 | Q12: 1
A13: East Jennifer | B13: 2 | C13: 2 | D13: 2 | F13: 10 | G13: 1 | H13: 7 | K13: 93 | L13: 3 | N13: 45592 | O13: 1 | P13: 1 | Q13: 1
A14: East Luisberg | B14: 4 | C14: 4 | D14: 4 | F14: 11 | G14: 0 | H14: 3 | K14: 81 | L14: 3 | N14: 45596 | O14: 1 | P14: 1 | Q14: 1
A15: East Melissaville | B15: 36 | C15: 36 | D15: 36 | F15: 12 | G15: 2 | H15: 0 | K15: 80 | L15: 3 | N15: 45608 | O15: 1 | P15: 1 | Q15: 1
... A53: West Richardchester | B53: 3 | C53: 3 | D53: 3 | F53: 50 | G53: 2 | H53: 4 | K53: 72 | L53: 1 | N53: 45736 | O53: 2 | P53: 2 | Q53: 2
A54: (blank) | B54: 3775 | D54: 10050 | F54: Grand Total | G54: 120 | H54: 150 | K54: 71 | L54: 1 | N54: 45737 | O54: 1 | P54: 1 | Q54: 1
A55: Grand Total | B55: 5050 | C55: 1275 | D55: 11325 | K55: 69 | L55: 1 | N55: 45741 | O55: 1 | P55: 1 | Q55: 1
K56: 67 | L56: 1 | N56: 45743 | O56: 1 | P56: 1 | Q56: 1
K57: 65 | L57: 1 | N57: 45747 | O57: 1 | P57: 1 | Q57: 1
K58: 62 | L58: 1 | N58: 45750 | O58: 1 | P58: 1 | Q58: 1
K59: 60 | L59: 1 | N59: 45756 | O59: 1 | P59: 1 | Q59: 1
K60: 58 | L60: 1 | N60: 45758 | O60: 1 | P60: 1 | Q60: 1
K61: 57 | L61: 1 | N61: 45759 | O61: 1 | P61: 1 | Q61: 1
K62: 55 | L62: 1 | N62: 45760 | O62: 1 | P62: 1 | Q62: 1
K63: 52 | L63: 1 | N63: 45761 | O63: 2 | P63: 2 | Q63: 2
K64: 48 | L64: 1 | N64: 45775 | O64: 1 | P64: 1 | Q64: 1
K65: 47 | L65: 1 | N65: 45776 | O65: 1 | P65: 1 | Q65: 1
K66: 38 | L66: 1 | N66: 45779 | O66: 1 | P66: 1 | Q66: 1
K67: 35 | L67: 1 | N67: 45781 | O67: 1 | P67: 1 | Q67: 1
... K81: 3 | L81: 1 | N81: 45842 | O81: 1 | P81: 1 | Q81: 1
K82: Grand Total | L82: 150 | N82: 45847 | O82: 1 | P82: 1 | Q82: 1
N83: 45850 | O83: 1 | P83: 1 | Q83: 1
N84: 45875 | O84: 1 | P84: 1 | Q84: 1
N85: 45880 | O85: 1 | P85: 1 | Q85: 1
N86: 45887 | O86: 1 | P86: 1 | Q86: 1
N87: 45888 | O87: 1 | P87: 1 | Q87: 1
N88: 45891 | O88: 2 | P88: 2 | Q88: 2
N89: 45904 | O89: 1 | P89: 1 | Q89: 1
N90: 45905 | O90: 1 | P90: 1 | Q90: 1
N91: 45910 | O91: 1 | P91: 1 | Q91: 1
N92: (blank) | O92: 50 | Q92: 20
...
